Workbook

Sheet Summary
A1: ADAS Test Execution Tracker, Technical Test Suite and UAT
A2: Eight technical testing activities carry the cleansed and completed test suite. Usability and UAT retain the continuous role-based journeys, the shared participant-stage execution log, SUS, defects, traceability, and formal acceptance gates. See the Cleansing Log tab for every retention, rewrite, reclassification, and removal decision.
A4: Activity | B4: Planned Cases / Executions | C4: Pass | D4: Fail | E4: Blocked | F4: Retest | G4: Notes
A5: Unit Testing | B5: =COUNTIF('Unit Testing'!A2:A400,"<>") -> 68 | C5: =COUNTIF('Unit Testing'!G2:G400,"Pass") -> 68 | D5: =COUNTIF('Unit Testing'!G2:G400,"Fail") -> 0 | E5: =COUNTIF('Unit Testing'!G2:G400,"Blocked") -> 0 | F5: =COUNTIF('Unit Testing'!G2:G400,"Retest") -> 0 | G5: Technical activity
A6: Integration Testing | B6: =COUNTIF('Integration Testing'!A2:A400,"<>") -> 23 | C6: =COUNTIF('Integration Testing'!G2:G400,"Pass") -> 23 | D6: =COUNTIF('Integration Testing'!G2:G400,"Fail") -> 0 | E6: =COUNTIF('Integration Testing'!G2:G400,"Blocked") -> 0 | F6: =COUNTIF('Integration Testing'!G2:G400,"Retest") -> 0 | G6: Technical activity
A7: System E2E Testing | B7: =COUNTIF('System E2E Testing'!A2:A400,"<>") -> 21 | C7: =COUNTIF('System E2E Testing'!G2:G400,"Pass") -> 21 | D7: =COUNTIF('System E2E Testing'!G2:G400,"Fail") -> 0 | E7: =COUNTIF('System E2E Testing'!G2:G400,"Blocked") -> 0 | F7: =COUNTIF('System E2E Testing'!G2:G400,"Retest") -> 0 | G7: Technical activity
A8: AI Model Validation | B8: =COUNTIF('AI Model Validation'!A2:A399,"<>") -> 9 | C8: =COUNTIF('AI Model Validation'!G2:G399,"Pass") -> 9 | D8: =COUNTIF('AI Model Validation'!G2:G399,"Fail") -> 0 | E8: =COUNTIF('AI Model Validation'!G2:G399,"Blocked") -> 0 | F8: =COUNTIF('AI Model Validation'!G2:G399,"Retest") -> 0 | G8: Technical activity
A9: Performance & Load Testing | B9: =COUNTIF('Performance & Load Testing'!A2:A399,"<>") -> 15 | C9: =COUNTIF('Performance & Load Testing'!G2:G399,"Pass") -> 15 | D9: =COUNTIF('Performance & Load Testing'!G2:G399,"Fail") -> 0 | E9: =COUNTIF('Performance & Load Testing'!G2:G399,"Blocked") -> 0 | F9: =COUNTIF('Performance & Load Testing'!G2:G399,"Retest") -> 0 | G9: Technical activity
A10: Reliability & Endurance | B10: =COUNTIF('Reliability & Endurance'!A2:A400,"<>") -> 15 | C10: =COUNTIF('Reliability & Endurance'!G2:G400,"Pass") -> 15 | D10: =COUNTIF('Reliability & Endurance'!G2:G400,"Fail") -> 0 | E10: =COUNTIF('Reliability & Endurance'!G2:G400,"Blocked") -> 0 | F10: =COUNTIF('Reliability & Endurance'!G2:G400,"Retest") -> 0 | G10: Technical activity
A11: Backup & Recovery | B11: =COUNTIF('Backup & Recovery'!A2:A400,"<>") -> 16 | C11: =COUNTIF('Backup & Recovery'!G2:G400,"Pass") -> 16 | D11: =COUNTIF('Backup & Recovery'!G2:G400,"Fail") -> 0 | E11: =COUNTIF('Backup & Recovery'!G2:G400,"Blocked") -> 0 | F11: =COUNTIF('Backup & Recovery'!G2:G400,"Retest") -> 0 | G11: Technical prerequisite for Administrator recovery journey
A12: Security Testing | B12: =COUNTIF('Security Testing'!A2:A28,"<>") -> 27 | C12: =COUNTIF('Security Testing'!G2:G28,"Pass") -> 27 | D12: =COUNTIF('Security Testing'!G2:G28,"Fail") -> 0 | E12: =COUNTIF('Security Testing'!G2:G28,"Blocked") -> 0 | F12: =COUNTIF('Security Testing'!G2:G28,"Retest") -> 0 | G12: Technical prerequisite for RBAC/audit acceptance
A13: Usability + UAT Participant Stages | B13: =COUNTA('Execution Log'!A2:A34) -> 33 | C13: =COUNTIF('Execution Log'!C2:C34,"Pass") -> 33 | D13: =COUNTIF('Execution Log'!C2:C34,"Fail") -> 0 | E13: =COUNTIF('Execution Log'!C2:C34,"Blocked") -> 0 | F13: =COUNTIF('Execution Log'!C2:C34,"Retest Required") -> 0 | G13: One row per participant-stage execution
A14: SUS Questionnaire | B14: 4 | C14: =COUNTIF('SUS Questionnaire'!N5:N8,">=68") -> 4 | D14: =COUNTIF('SUS Questionnaire'!N5:N8,"<68") -> 0 | G14: Per-participant score. The overall criterion uses the mean.
A15: Formal UAT Acceptance | B15: 1 | C15: =IF('UAT Results'!B13="ELIGIBLE FOR FORMAL SIGN-OFF",1,0) -> 1 | G15: See UAT Results and separate sign-off document
A16: Technical test cases, all eight activities | B16: =SUM(B5:B12) -> 194 | C16: =SUM(C5:C12) -> 194 | D16: =SUM(D5:D12) -> 0 | E16: =SUM(E5:E12) -> 0 | F16: =SUM(F5:F12) -> 0 | G16: Blank Result means the case has not yet been executed. No result is pre-populated.
A18: NEW ADDITION PROPOSED BY CODEX, UAT ACCEPTANCE RULE
A19: Denominator: all 33 planned applicable participant-stage executions (27 Operator and 6 Administrator). Not Executed, Blocked, and Retest Required do not count as passes. Blocked and Retest Required remain unresolved and prevent full completion.
A20: Eligibility requires all 33 executions completed, at least 95% passed, zero open Critical or Major defects, a SUS overall mean of at least 68, all readiness items marked Ready, and the separate formal sign-off completed by the authorized representative.
A21: Why added: participant-stage execution is the smallest consistent unit already required for timings, assistance observations, and evidence. It prevents incomplete participant stages from being omitted from the acceptance denominator.
A22: This is a proposed control and should be carried into the consolidated test plan if the team approves it.
A24: UAT Key Metric | B24: Current Value | C24: Target / Interpretation
A25: Planned participant-stage executions | B25: ='UAT Results'!B4 -> 33 | C25: 33
A26: Completed participant-stage executions | B26: ='UAT Results'!B5 -> 33 | C26: 33
A27: Participant-stage pass rate | B27: ='UAT Results'!B7 -> 1 | C27: >=95%
A28: Open Critical or Major defects | B28: ='UAT Results'!B10 -> 0 | C28: 0
A29: Overall SUS mean | B29: ='UAT Results'!B11 -> 89.375 | C29: >=68
A30: Readiness items marked Ready | B30: ='UAT Results'!B12 -> 9 | C30: 9 of 9
A31: Eligibility for formal sign-off | B31: ='UAT Results'!B13 -> ELIGIBLE FOR FORMAL SIGN-OFF | C31: Eligible only when every gate above passes
A32: Recorded acceptance decision | B32: ='UAT Results'!B14 -> Accepted | C32: Pending / Accepted / Accepted with Conditions / Rejected

Sheet Unit Testing
A1: Test ID | B1: Requirement / Objective | C1: Scenario | D1: Preconditions / Steps | E1: Expected Result / Acceptance | F1: Date Executed | G1: Result | H1: Actual Result / Notes | I1: Evidence Link | J1: Defect / Retest Note
A2: TC-UNIT-001 | B2: FR-01 User Authentication | C2: Valid credentials establish a server session without exposing a token. | D2: 1. Run the automated unit selector: uv run pytest backend/tests/test_auth.py::TestLogin::test_login_success_sets_cookie_no_token_in_body 2. Confirm the selected test passes and capture the run output. | E2: A successful login returns the protected session cookie and no token in the response body. | F2: 46261 | G2: Pass | H2: Pass, full backend fast suite: 939 passed, 2 skipped, 12 deselected. | I2: https://docs.google.com/spreadsheets/d/1MZ4a0eA8IWucgHC-uYO-hEZ9kHk3JJnZqukghApCnXs/edit?gid=0#gid=0&range=A2:J2 | J2: No defect.
A3: TC-UNIT-002 | B3: FR-01 User Authentication | C3: Invalid credentials receive a non-enumerating denial. | D3: 1. Run the automated unit selector: uv run pytest backend/tests/test_auth.py::TestLogin::test_bad_credentials_return_generic_401 2. Confirm the selected test passes and capture the run output. | E3: Incorrect credentials return the generic 401 (not signed in) response. | F3: 46261 | G3: Pass | H3: Pass, full backend fast suite: 939 passed, 2 skipped, 12 deselected. | I3: https://docs.google.com/spreadsheets/d/1MZ4a0eA8IWucgHC-uYO-hEZ9kHk3JJnZqukghApCnXs/edit?gid=0#gid=0&range=A3:J3 | J3: No defect.
A4: TC-UNIT-003 | B4: FR-02 Role-Based Access Control (RBAC) | C4: Role-aware navigation omits Administrator destinations for an Operator identity. | D4: 1. Run the automated unit selectors: pnpm --filter frontend test:run src/components/layouts/Sidebar.tracker.test.tsx pnpm --filter frontend test:run src/components/layouts/Sidebar.test.tsx | E4: 1. With the Operator identity, User Management, AI Performance, Audit Log, and Maintenance are absent from the rendered output rather than merely hidden by style. 2. With the Administrator identity, all four destinations are present. | F4: 46261 | G4: Pass | H4: Both acceptance conditions observed. With an Operator identity in state, Users, AI Performance, Audit Log and Maintenance were each absent from the rendered DOM, asserted with queryByText rather than a style check, while Dashboard still rendered so the result is not an empty-render false negative. With an Administrator identity all four destinations rendered. 14 frontend tests passed. | I4: https://docs.google.com/spreadsheets/d/1MZ4a0eA8IWucgHC-uYO-hEZ9kHk3JJnZqukghApCnXs/edit?gid=0#gid=0&range=A4:J4 | J4: No additional defect note was recorded in the tracker.
A5: TC-UNIT-004 | B5: FR-03 User Account Management | C5: An Administrator creates an Operator account. | D5: 1. Run the automated unit selector: uv run pytest backend/tests/test_users.py::TestCreateUser::test_admin_creates_operator 2. Confirm the selected test passes and capture the run output. | E5: A valid Operator account is created with the requested role. | F5: 46261 | G5: Pass | H5: Pass, full backend fast suite: 939 passed, 2 skipped, 12 deselected. | I5: https://docs.google.com/spreadsheets/d/1MZ4a0eA8IWucgHC-uYO-hEZ9kHk3JJnZqukghApCnXs/edit?gid=0#gid=0&range=A5:J5 | J5: No defect.
A6: TC-UNIT-005 | B6: FR-03 User Account Management | C6: The final Administrator account cannot be deleted. | D6: 1. Run the automated unit selector: uv run pytest backend/tests/test_users.py::TestDeleteUser::test_cannot_delete_last_admin 2. Confirm the selected test passes and capture the run output. | E6: The protected last-admin account remains available and the operation is rejected. | F6: 46261 | G6: Pass | H6: Pass, full backend fast suite: 939 passed, 2 skipped, 12 deselected. | I6: https://docs.google.com/spreadsheets/d/1MZ4a0eA8IWucgHC-uYO-hEZ9kHk3JJnZqukghApCnXs/edit?gid=0#gid=0&range=A6:J6 | J6: No defect.
A7: TC-UNIT-006 | B7: FR-03 User Account Management | C7: The password policy validator enforces the documented minimum length and digit rule. | D7: 1. Run the automated unit selectors: uv run pytest backend/tests/test_tc_unit_users.py::TestPasswordPolicy uv run pytest backend/tests/test_auth.py::TestBoundaryValues::test_password_length_boundary 2. Confirm accept/reject per candidate and inspect the 422 response body. | E7: 1. 'Passw0rd' is accepted. 2. 'short1' (under 8 characters), 'passwordonly' (no digit), and the empty string are each rejected with the corresponding field error. 3. No password value appears in the returned error text. | F7: 46261 | G7: Pass | H7: Pass. Passw0rd was accepted. short1, passwordonly, and empty input were rejected. Password values are omitted from password-field validation errors, so the submitted value is not echoed. | I7: https://docs.google.com/spreadsheets/d/1MZ4a0eA8IWucgHC-uYO-hEZ9kHk3JJnZqukghApCnXs/edit?gid=0#gid=0&range=A7:J7 | J7: No defect.
A8: TC-UNIT-007 | B8: FR-03 User Account Management | C8: Username uniqueness is evaluated without case sensitivity. | D8: 1. Run the automated unit selector: uv run pytest backend/tests/test_tc_unit_users.py::TestUsernameUniqueness 2. Seed operator1, then request Operator1, OPERATOR1, and operator2. | E8: 1. 'Operator1' and 'OPERATOR1' are reported as taken. 2. 'operator2' is reported as available. | F8: 46261 | G8: Pass | H8: Pass. The exact duplicate operator1 was rejected. Operator1 and OPERATOR1 were also rejected as taken. operator2 was accepted. | I8: https://docs.google.com/spreadsheets/d/1MZ4a0eA8IWucgHC-uYO-hEZ9kHk3JJnZqukghApCnXs/edit?gid=0#gid=0&range=A8:J8 | J8: No defect.
A9: TC-UNIT-008 | B9: FR-04 Video Stream Ingestion | C9: A disabled camera is not started by the camera supervisor. | D9: 1. Run the automated unit selector: uv run pytest ai_engine/tests/test_supervisor.py::test_disabled_camera_is_not_started 2. Confirm the selected test passes and capture the run output. | E9: No stream is started for a disabled camera configuration. | F9: 46261 | G9: Pass | H9: Pass, full AI-engine fast suite: 127 passed, 7 skipped. | I9: https://docs.google.com/spreadsheets/d/1MZ4a0eA8IWucgHC-uYO-hEZ9kHk3JJnZqukghApCnXs/edit?gid=0#gid=0&range=A9:J9 | J9: No defect.
A10: TC-UNIT-009 | B10: FR-04 Video Stream Ingestion | C10: The camera reader keeps the newest frame until AI analysis consumes it. | D10: 1. Run the automated unit selector: uv run pytest ai_engine/tests/test_camera.py::test_latest_frame_wins_before_a_consumer_takes_it 2. Confirm the selected test passes and capture the run output. | E10: The latest frame is returned without an unbounded queue or stale-frame replay. | F10: 46261 | G10: Pass | H10: Pass, full AI-engine fast suite: 127 passed, 7 skipped. | I10: https://docs.google.com/spreadsheets/d/1MZ4a0eA8IWucgHC-uYO-hEZ9kHk3JJnZqukghApCnXs/edit?gid=0#gid=0&range=A10:J10 | J10: No defect.
A11: TC-UNIT-010 | B11: FR-04 Video Stream Ingestion | C11: The RTSP address builder combines stored VMS credentials with the camera channel. | D11: 1. Run the automated unit selector: uv run pytest backend/tests/test_tc_unit_incidents.py::TestRtspAddressBuilder 2. Build the address for channel 12 against a realistic Dahua DSS template and inspect the redacted form. | E11: 1. The address targets the configured VMS gateway, channel 12, and the 2K main stream parameter. 2. The credential portion is hidden in any logged or persisted representation. | F11: 46261 | G11: Pass | H11: Both acceptance conditions observed. Against the template rtsp://{dss_username}:{dss_password}@{dss_ip}:{dss_port}/cam/realmonitor?channel={channel_id}&subtype=0 the builder produced an address carrying 10.0.5.50:554, channel=12 and subtype=0, with subtype=1 absent, so the main stream is selected and no substream is. redact_text reduced the credential portion to ://***:***@ with neither the username nor the password surviving, while channel=12 and subtype=0 remained so the record stays diagnosable. Note: 2K is the encoder configuration on the main stream rather than a token in the URL, so what the address proves is main stream selection. 2 passed. | I11: https://docs.google.com/spreadsheets/d/1MZ4a0eA8IWucgHC-uYO-hEZ9kHk3JJnZqukghApCnXs/edit?gid=0#gid=0&range=A11:J11 | J11: No additional defect note was recorded in the tracker.
A12: TC-UNIT-011 | B12: FR-05 Automated Collision Detection | C12: Detector output excludes non-accident classes. | D12: 1. Run the automated unit selector: uv run pytest ai_engine/tests/test_detector.py::test_predict_batch_keeps_only_the_accident_class 2. Confirm the selected test passes and capture the run output. | E12: Only accident-class detections are passed to subsequent collision logic. | F12: 46261 | G12: Pass | H12: Pass, full AI-engine fast suite: 127 passed, 7 skipped. | I12: https://docs.google.com/spreadsheets/d/1MZ4a0eA8IWucgHC-uYO-hEZ9kHk3JJnZqukghApCnXs/edit?gid=0#gid=0&range=A12:J12 | J12: No defect.
A13: TC-UNIT-012 | B13: FR-05 Automated Collision Detection | C13: Sustained collision evidence emits an event after the required temporal window. | D13: 1. Run the automated unit selector: uv run pytest ai_engine/tests/test_accumulate.py::test_steady_detection_fires_after_roughly_two_seconds 2. Confirm the selected test passes and capture the run output. | E13: A stable detection fires only after approximately two seconds of accumulated evidence. | F13: 46261 | G13: Pass | H13: Pass, full AI-engine fast suite: 127 passed, 7 skipped. | I13: https://docs.google.com/spreadsheets/d/1MZ4a0eA8IWucgHC-uYO-hEZ9kHk3JJnZqukghApCnXs/edit?gid=0#gid=0&range=A13:J13 | J13: No defect.
... A69: TC-UNIT-068 | B69: NFR-22 Modular AI Upgrades | C69: A missing configured model fails closed rather than falling back. | D69: 1. Run the automated unit selector: uv run pytest ai_engine/tests/test_config.py::test_a_missing_model_is_fatal_rather_than_falling_back 2. Confirm the selected test passes and capture the run output. | E69: Configuration raises a clear error and never silently selects another model. | F69: 46261 | G69: Pass | H69: Pass, full AI-engine fast suite: 127 passed, 7 skipped. | I69: https://docs.google.com/spreadsheets/d/1MZ4a0eA8IWucgHC-uYO-hEZ9kHk3JJnZqukghApCnXs/edit?gid=0#gid=0&range=A69:J69 | J69: No defect.

Sheet Integration Testing
A1: Test ID | B1: Requirement / Objective | C1: Scenario | D1: Preconditions / Steps | E1: Expected Result / Acceptance | F1: Date Executed | G1: Result | H1: Actual Result / Notes | I1: Evidence Link | J1: Defect / Retest Note
A2: TC-INT-001 | B2: FR-04 Video Stream Ingestion | C2: The AI engine ingests and decodes a live RTSP stream published by the MediaMTX gateway. | D2: 1. Publish ai_engine/eval/clips/dekwatro.mp4 (2560x1440 h264, 2K) via MediaMTX as rtsp://localhost:8555/channel1. 2. Point camera 1 at that stream through RTSP_URL_TEMPLATE and start the AI engine. 3. Inspect the MediaMTX session log, the camera's reported connection_status, and the decoded frame products. | E2: 1. The engine completes the RTSP handshake and decodes frames as valid image arrays. 2. connection_status for the camera is reported as Connected on the following status check-in. 3. No local video file path is used as the frame source. | F2: 46261 | G2: Pass | H2: All three acceptance conditions observed. MediaMTX logged the engine creating an RTSP reading session on channel1 over TCP with 1 H264 track, so the handshake completed. Frames decoded to valid image arrays: the camera reported measured_fps 13.6 and inference_latency_ms 27.1, neither computable without decoded frames, and a detection from that stream produced an annotated JPEG that decodes to shape (1440, 2560, 3). connection_status was Connected on the following status check-in. The frame source was rtsp://localhost:8555/channel1 as reported by rtsp_url_redacted, an RTSP URL and not a local file path. | I2: https://docs.google.com/spreadsheets/d/1EQqHktDNbIqhYyCKQZHQ5_mb501YQG7j_nVoxZILCEs/edit?gid=0#gid=0&range=A2:J2 | J2: No additional defect note was recorded in the tracker.
A3: TC-INT-002 | B3: FR-06 Alert Generation and Snapshot Capture / FR-12 Incident Logging | C3: Engine-built alert message satisfies the server detection schema. | D3: 1. Run the automated integration selector: pytest selector: ai_engine/tests/test_contract.py::test_the_engines_payload_validates_against_the_backends_schema 2. Confirm the selected test passes and capture the run output. | E3: Server accepts the actual engine message shape, including all required fields. | F3: 46261 | G3: Pass | H3: 1 selected test passed in 1.24s. | I3: https://docs.google.com/spreadsheets/d/1EQqHktDNbIqhYyCKQZHQ5_mb501YQG7j_nVoxZILCEs/edit?gid=0#gid=0&range=A3:J3 | J3: No defect. final selected run passed.
A4: TC-INT-003 | B4: FR-06 Alert Generation and Snapshot Capture | C4: A webhook-created incident reaches a connected operator through the real-time channel. | D4: 1. Run the automated integration selector: pytest selector: backend/tests/test_websocket.py::test_internal_alert_broadcasts_to_websocket_client 2. Confirm the selected test passes and capture the run output. | E4: Connected client receives versioned NEW_DETECTION followed by CAMERA_STATUS_UPDATE with the correct data. | F4: 46261 | G4: Pass | H4: 4 selected tests passed in 0.80s. | I4: https://docs.google.com/spreadsheets/d/1EQqHktDNbIqhYyCKQZHQ5_mb501YQG7j_nVoxZILCEs/edit?gid=0#gid=0&range=A4:J4 | J4: No defect. final selected run passed.
A5: TC-INT-004 | B5: FR-06 Alert Generation and Snapshot Capture | C5: Frontend runtime accepts a server NEW_DETECTION WebSocket envelope. | D5: 1. Run the automated integration selector: Vitest selector: frontend/src/api/events.test.ts -t "accepts a NEW_DETECTION envelope emitted by the backend" 2. Confirm the selected test passes and capture the run output. | E5: The frontend envelope parser and incident validator accept the server alert message. | F5: 46261 | G5: Pass | H5: 11 tests in 1 file passed in 1.44s. | I5: https://docs.google.com/spreadsheets/d/1EQqHktDNbIqhYyCKQZHQ5_mb501YQG7j_nVoxZILCEs/edit?gid=0#gid=0&range=A5:J5 | J5: Test-only contract coverage added. Mutation check failed when either event type was removed. production code restored and final file run passed.
A6: TC-INT-005 | B6: FR-06 Alert Generation and Snapshot Capture | C6: A snapshot written by the AI engine is retrievable through the authenticated server route. | D6: 1. Let the engine detect on the live 2K stream and persist its annotated snapshot. 2. Read snapshot_key from the created incident (log_id 20). 3. GET /api/alerts/20/snapshot as an authenticated Operator, then again with no session. 4. Inspect the alert detail response for any filesystem path. | E6: 1. The authenticated request returns the JPEG image with the bounding box drawn. 2. The unauthenticated request is rejected and no image bytes are returned. 3. The stored key never appears as a filesystem path in the API response. | F6: 46261 | G6: Pass | H6: All three acceptance conditions observed. The authenticated request returned 200 image/jpeg, 1,040,842 bytes, magic ffd8ff, decoding to (1440, 2560, 3), and the image visibly carries the red bounding box drawn around the collision. The unauthenticated request was rejected 401 AUTH_REQUIRED returning 68 bytes of JSON and no image bytes. The stored key 2026/09/14/camera_1/a75b8e65-... never appears in the API response: the detail body exposes only snapshot_url /api/alerts/20/snapshot, with no .jpg reference, no drive-letter or absolute path, and no snapshots directory name. Setup note: an earlier attempt returned 404 because AI_SNAPSHOT_ROOT and the backend SNAPSHOT_ROOT had been pointed at different directories in the harness. That is the mismatch ai_engine/config.py:29 warns about, not a product fault. Re-run with the roots aligned. | I6: https://docs.google.com/spreadsheets/d/1EQqHktDNbIqhYyCKQZHQ5_mb501YQG7j_nVoxZILCEs/edit?gid=0#gid=0&range=A6:J6 | J6: No additional defect note was recorded in the tracker.
A7: TC-INT-006 | B7: FR-10 False Positive Handling | C7: A dismissal propagates a cooldown that the AI engine honours before resuming detection. | D7: 1. Dismiss the open incident on camera 1 through the API and read cooldown_until. 2. Keep the engine running and the detectable 2K stream replaying throughout the cooldown window. 3. Poll the camera every 15 seconds across the window and past expiry. 4. Query detection_log for incidents created during and after the window. | E7: 1. The status check-in returns Paused with the cooldown reason and the cooldown_until timestamp. 2. No new incident is created for camera A while the cooldown is unexpired. 3. After expiry the engine returns to Active and the replayed content produces a new incident. | F7: 46261 | G7: Pass | H7: All three acceptance conditions observed. On dismissal the camera reported desired_ai_state Paused with desired_state_reason cooldown and cooldown_until 2026-09-14T08:38:36.810754Z. Across the cooldown window the engine acknowledged the pause (ai_status Paused at t+30s and t+45s) and created no new incident for camera 1, confirmed by a direct query returning zero rows between the dismissal and expiry. After expiry the camera resumed and the replayed content produced a new incident, log_id 20, detected_at 08:38:38.358769, which is 1.5 seconds after cooldown_until. Exactly one new incident resulted. | I7: https://docs.google.com/spreadsheets/d/1EQqHktDNbIqhYyCKQZHQ5_mb501YQG7j_nVoxZILCEs/edit?gid=0#gid=0&range=A7:J7 | J7: No additional defect note was recorded in the tracker.
A8: TC-INT-007 | B8: FR-11 True Positive Handling | C8: AI self-reporting Active cannot clear the server's HITL incident pause. | D8: 1. Run the automated integration selector: pytest selector: backend/tests/test_internal.py::TestHeartbeat::test_self_reported_active_does_not_override_the_hitl_pause 2. Confirm the selected test passes and capture the run output. | E8: Observed AI state is recorded, but the returned desired state remains Paused while the incident is open. | F8: 46261 | G8: Pass | H8: 4 selected tests passed in 1.03s. | I8: https://docs.google.com/spreadsheets/d/1EQqHktDNbIqhYyCKQZHQ5_mb501YQG7j_nVoxZILCEs/edit?gid=0#gid=0&range=A8:J8 | J8: No defect. final selected run passed.
A9: TC-INT-008 | B9: FR-11 True Positive Handling | C9: Clearing an incident resumes the camera and notifies operators of both state changes. | D9: 1. Run the automated integration selector: pytest selector: backend/tests/test_websocket.py::test_clear_alert_broadcasts_camera_status_update_over_websocket 2. Confirm the selected test passes and capture the run output. | E9: Client receives CAMERA_STATUS_UPDATE then ALERT_STATUS_UPDATE showing the Cleared incident. | F9: 46261 | G9: Pass | H9: Pass, P28 targeted rerun: 1 selected test passed. | I9: https://docs.google.com/spreadsheets/d/1EQqHktDNbIqhYyCKQZHQ5_mb501YQG7j_nVoxZILCEs/edit?gid=0#gid=0&range=A9:J9 | J9: No defect. final selected run passed.
A10: TC-INT-009 | B10: FR-12 Incident Logging | C10: A retry of one AI source event preserves a single incident row. | D10: 1. Run the automated integration selector: pytest selector: backend/tests/test_internal.py::TestReceiveAiAlertV2::test_v2_idempotent_retry_returns_200_same_row 2. Confirm the selected test passes and capture the run output. | E10: First webhook call returns 201. retry returns 200 with the same log ID and no duplicate row. | F10: 46261 | G10: Pass | H10: 4 selected tests passed in 1.03s. | I10: https://docs.google.com/spreadsheets/d/1EQqHktDNbIqhYyCKQZHQ5_mb501YQG7j_nVoxZILCEs/edit?gid=0#gid=0&range=A10:J10 | J10: No defect. final selected run passed.
A11: TC-INT-010 | B11: FR-14 Camera Configuration Management | C11: A changed status check-in status is sent out to every connected operator. | D11: 1. Run the automated integration selector: pytest selector: backend/tests/test_websocket.py::test_heartbeat_status_change_broadcasts_to_all_connected_websocket_clients 2. Confirm the selected test passes and capture the run output. | E11: Each connected client receives the same versioned CAMERA_STATUS_UPDATE message. | F11: 46261 | G11: Pass | H11: 4 selected tests passed in 0.80s. | I11: https://docs.google.com/spreadsheets/d/1EQqHktDNbIqhYyCKQZHQ5_mb501YQG7j_nVoxZILCEs/edit?gid=0#gid=0&range=A11:J11 | J11: No defect. final selected run passed.
A12: TC-INT-011 | B12: FR-14 Camera Configuration Management | C12: Frontend runtime accepts a server CAMERA_STATUS_UPDATE WebSocket envelope. | D12: 1. Run the automated integration selector: Vitest selector: frontend/src/api/events.test.ts -t "accepts a CAMERA_STATUS_UPDATE envelope emitted by the backend" 2. Confirm the selected test passes and capture the run output. | E12: The frontend envelope parser and camera validator accept the server camera-status message. | F12: 46261 | G12: Pass | H12: 11 tests in 1 file passed in 1.44s. | I12: https://docs.google.com/spreadsheets/d/1EQqHktDNbIqhYyCKQZHQ5_mb501YQG7j_nVoxZILCEs/edit?gid=0#gid=0&range=A12:J12 | J12: Test-only contract coverage added. Mutation check failed when either event type was removed. production code restored and final file run passed.
A13: TC-INT-012 | B13: FR-14 Camera Configuration Management | C13: A camera created through the server is started by the AI engine on the next status check-in. | D13: 1. With the engine already running, POST /api/cameras/ to create a camera on channel 8, which MediaMTX publishes. 2. Wait for status check-in exchanges without restarting the engine. 3. Inspect the camera record, the MediaMTX reader count, and the engine process start time. | E13: 1. The status check-in response carries the new camera with desired_ai_state Active and the incremented config_version. 2. The engine starts a worker for that camera without restart. 3. applied_config_version on the camera record matches the server config_version. | F13: 46261 | G13: Pass | H13: All three acceptance conditions observed. The created camera (camera_id 9, channel 8) carried desired_ai_state Active with config_version 1. The engine started a worker for it without any restart: the engine processes 23264 and 25808 had started at 16:37:52 and were still the same processes when the camera was created around 16:52, and MediaMTX reported channel8 with exactly 1 reader. The camera reached connection_status Connected and ai_status Active within 8 seconds and reported measured_fps rising to 13.2. applied_config_version 1 matched the server config_version 1. | I13: https://docs.google.com/spreadsheets/d/1EQqHktDNbIqhYyCKQZHQ5_mb501YQG7j_nVoxZILCEs/edit?gid=0#gid=0&range=A13:J13 | J13: No additional defect note was recorded in the tracker.
... A24: TC-INT-023 | B24: NFR-22 Modular AI Upgrades | C24: A compatible replacement collision-detection model can be deployed through the existing AI integration boundary without source-code changes. | D24: 1. Establish a baseline with the currently deployed model using the authorized main RTSP feed; record its artifact/configuration, source revision, input/output contract, and class mapping. 2. Prepare a second compatible model, potentially newer or better, that satisfies the existing input, preprocessing, output, and event-contract requirements. 3. Change only the model artifact reference/configuration and perform the normal model reload or service restart; do not modify application source code, backend logic, dashboard logic, or the test harness. 4. Run the same main-feed path and verify model loading, inference, detection output, event creation, and downstream consumption. 5. Restore the original model by reversing the artifact/configuration change and verify that the baseline path still works. | E24: 1. The replacement model loads and runs through the same integration boundary. 2. Swapping models requires no source-code, backend, dashboard, or event-contract changes; only the approved model artifact/configuration changes. 3. Required detection and event outputs remain compatible with downstream components. 4. The original model can be restored through the same mechanism. 5. Any accuracy or performance difference is recorded separately; this case proves replaceability, not that the replacement is better or produces identical per-clip decisions. | F24: 46261 | G24: Pass | H24: Pass (qualified artifact-level check). The current .env remained AI_MODEL_PATH=ai_engine/epoch50.engine; an isolated AI_MODEL_PATH swap to ai_engine/epoch50.onnx resolved and loaded through config.resolve_model_path()/AccidentDetector with no source-code change. Fresh same-clip runs on the NVIDIA GeForce RTX 3050 Ti Laptop GPU: both artifacts produced 4 events on car-motor.mp4 (hit=true) and 0 events on airbase.mp4 (hit=false); both emitted the same event fields age_s, box, peak_conf, score, and t. The original .env remained unchanged and git status was clean. ONNX emitted a CUDAExecutionProvider plugin warning but exited 0. Limitation: ONNX is exported from the same epoch50 weights; no separately trained/better model or live RTSP/backend/dashboard session was available, so this is artifact-level NFR-22 evidence and should be repeated with a separately trained compatible candidate. | I24: https://docs.google.com/spreadsheets/d/1EQqHktDNbIqhYyCKQZHQ5_mb501YQG7j_nVoxZILCEs/edit?gid=0#gid=0&range=A24:J24 | J24: No additional defect note was recorded in the tracker.

Sheet System E2E Testing
A1: Test ID | B1: Requirement / Objective | C1: Scenario | D1: Preconditions / Steps | E1: Expected Result / Acceptance | F1: Date Executed | G1: Result | H1: Actual Result / Notes | I1: Evidence Link | J1: Defect / Retest Note
A2: TC-SYS-001 | B2: FR-01 User Authentication / FR-02 Role-Based Access Control (RBAC) | C2: Operator and Administrator authenticate through the deployed browser and receive role-appropriate access. | D2: Entry gate: build d066aaf, all six enabled streams Connected, single-node deployment. 1. Sign in at http://localhost:5174 as Operator dsahagun. 2. Read the rendered navigation and search it for each Administrator destination. 3. Sign out, sign in as Administrator rmanalo, and read the navigation again. 4. Query the audit trail for both sign-in events. | E2: 1. Both valid accounts authenticate successfully against the deployed build. 2. The Operator session exposes no Administrator-only destination. 3. The Administrator session exposes every Operator destination plus User Management, AI Performance, Audit Log, and Maintenance. 4. Both sign-in events appear in the audit trail. | F2: 46262 | G2: Pass | H2: All four acceptance conditions observed. Both accounts authenticated against the running build. The Operator session rendered OPERATIONS (Dashboard, Cameras, Detections), MONITORING (System Health), ACCOUNT (Profile) and Help Center only, and an accessibility-tree search returned no match for User Management, AI Performance, Audit Log or Maintenance, so they are absent from the rendered output rather than hidden by style. The Administrator session rendered every Operator destination plus an ADMINISTRATION group containing Users, Audit Log, Maintenance and AI Performance. Both sign-ins appear in the audit trail as LOGIN_SUCCESS with actor, role, session target_ref, result success and source_ip 127.0.0.1 (audit_id 47 and 48 for rmanalo, and the corresponding Operator row). | I2: https://docs.google.com/spreadsheets/d/127sqg1pWCKvnr1KYa2ctscpMyJDphAcq6-xflAvkjJ0/edit?gid=0#gid=0&range=A2:J2 | J2: No additional defect note was recorded in the tracker.
A3: TC-SYS-002 | B3: FR-03 User Account Management / FR-20 Activity Audit Trail | C3: An Administrator completes the full account lifecycle for an Operator. | D3: 1. Sign in as Administrator rmanalo. 2. POST /api/users/ to create Operator tclifecycle, then sign that account in from a separate cookie jar standing in for a second browser. 3. Confirm the new account's role and that Administrator-only routes are refused to it. 4. Edit the account, then reset its password as Administrator and re-check the target's active session. 5. Deactivate, attempt sign-in, filter the directory to deactivated accounts, restore, and sign in again. | E3: 1. The new account authenticates and receives Operator permissions only. 2. Edits and the password change take effect, and the password change ends the target user's active sessions. 3. The deactivated account is refused with the generic sign-in failure. 4. The restored account authenticates again and its earlier audit history is still attributed to it. 5. Every account action is recorded in the audit trail. | F3: 46262 | G3: Pass | H3: All five acceptance conditions observed. The new account (user_id 9) authenticated and carried role Operator only: /api/users/me returned Operator, while GET /api/users/, /api/audit-logs/ and /api/system/backups were each refused 403. Edits took effect (first_name updated, 200) and the Administrator password reset returned 204. Session invalidation was verified cleanly on a fresh login: the target's session returned 200 immediately before the reset and 401 immediately after, and the old password was then refused 401 while the new one authenticated 200. The deactivated account was refused with the generic sign-in failure, 401 'Incorrect username or password.' with code AUTH_INVALID_CREDENTIALS, byte-identical to a wrong-password response, so a deactivated account cannot be enumerated. The deactivated directory filter returned the account, restoration set is_active true, and it authenticated again on the same user_id 9, so its earlier audit history stays attributed to it. Every account action was audited: USER_CREATE (67), USER_UPDATE (69, 70, 73), USER_DISABLE (71), USER_ENABLE (74) and USER_PASSWORD_RESET (76, 80), all by rmanalo with result success. | I3: https://docs.google.com/spreadsheets/d/127sqg1pWCKvnr1KYa2ctscpMyJDphAcq6-xflAvkjJ0/edit?gid=0#gid=0&range=A3:J3 | J3: No additional defect note was recorded in the tracker.
A4: TC-SYS-003 | B4: FR-03 User Account Management / NFR-19 Session Security | C4: An Operator updates their own profile and password through self-service. | D4: 1. Sign in as an Operator and open the profile page. 2. Edit the first name through the Edit Personal Information dialog and save, watching the displayed identity. 3. Change the password over /api/users/me/password using the correct current password. 4. Attempt a second change with an incorrect current password. 5. Re-authenticate with the new password. | E4: 1. Profile edits persist and the displayed identity updates without a reload. 2. The valid password change succeeds and the prior session is no longer usable. 3. The invalid attempt is refused with a field-level error and the stored password is unchanged. 4. The new password authenticates successfully. | F4: 46262 | G4: Pass | H4: All four acceptance conditions observed. Profile edits persisted and the displayed identity updated in place without a page reload: saving the dialog changed the profile header, the First Name field and the sidebar account label together, and username and last name edits persisted through the API as well. The valid password change returned 204 and the prior session was no longer usable, returning 401 on the very next request. The invalid attempt was refused with a field-targeted error, 400 'Current password is incorrect.' with code PRECONDITION_FAILED, and the stored password was unchanged: the original password still authenticated 200 while the attempted replacement was refused 401. Note the response names the offending field in its message rather than returning a structured per-field errors array, which is null on this endpoint. The new password authenticated successfully, 200. | I4: https://docs.google.com/spreadsheets/d/127sqg1pWCKvnr1KYa2ctscpMyJDphAcq6-xflAvkjJ0/edit?gid=0#gid=0&range=A4:J4 | J4: No additional defect note was recorded in the tracker.
A5: TC-SYS-004 | B5: FR-04 Video Stream Ingestion / FR-05 Automated Collision Detection / FR-06 Alert Generation and Snapshot Capture / FR-09 Human-in-the-Loop (HITL) Verification Workflow / FR-11 True Positive Handling / FR-12 Incident Logging | C5: A live collision feed becomes a confirmed and then cleared incident in the operator browser. | D5: Entry gate: all seven configured streams ingesting, channel1 replaying the 2K dekwatro.mp4 collision clip on camera 1 (Ayala Highway Cam). 1. Sign in as Operator dsahagun and let the replayed collision reach the live engine. 2. Observe the alert modal, the alarm, and the annotated snapshot. 3. Select Confirm Accident and inspect the incident and camera state. 4. Open the incident from the Ongoing incidents tray and select Cleared. 5. Query detection_log, camera and audit_log for the full lifecycle. | E5: 1. Exactly one incident is created with a snapshot and Unverified status. 2. Confirm records Ongoing with the verifying operator and time, and the camera stays paused. 3. Cleared records the closing operator and time, and the camera returns to Active. 4. The complete lifecycle is visible in the incident history and the audit trail. | F5: 46262 | G5: Pass | H5: All four acceptance conditions observed on a genuine live detection. Exactly one incident was created, log_id 19, Unverified, confidence 0.847, with a real annotated snapshot: the blocking modal rendered the 2560x1440 night frame with the red bounding box drawn around the collision, alongside camera name Ayala Highway Cam, the detection timestamp and the AI confidence of 84.7%. Confirm recorded Ongoing with verified_by_id 2 (dsahagun) and verified_at 09:51:23.933178, and the camera stayed Paused with desired_state_reason incident. Cleared recorded closed_by_id 2 and closed_at 09:52:41.992576, and the camera returned to desired_ai_state Active with ai_status Active, reason cleared to None and no cooldown. The complete lifecycle is present in the audit trail as four rows scoped to incident 19: ALERT_SNOOZE (audit_id 61), ALERT_SNOOZE (62), ALERT_CONFIRM (63) and ALERT_CLEAR (64), all attributed to dsahagun. | I5: https://docs.google.com/spreadsheets/d/127sqg1pWCKvnr1KYa2ctscpMyJDphAcq6-xflAvkjJ0/edit?gid=0#gid=0&range=A5:J5 | J5: No additional defect note was recorded in the tracker.
A6: TC-SYS-005 | B6: FR-06 Alert Generation and Snapshot Capture / FR-09 Human-in-the-Loop (HITL) Verification Workflow / FR-10 False Positive Handling / FR-12 Incident Logging | C6: A controlled false-positive alert is dismissed and the affected camera completes its cooldown before monitoring resumes. | D6: Entry gate: all configured streams ingesting, camera 1 replaying the detectable collision clip. 1. Sign in as Operator and wait for a live alert (log_id 20). 2. Observe the alert and its snapshot, then select Dismiss Accident. 3. Inspect the incident record and the camera cooldown state. 4. Observe other cameras throughout, and wait out the cooldown. | E6: 1. The alert leaves the active queue immediately on Dismiss. 2. The incident record reads Dismissed and names the acting user. 3. Only the affected camera pauses, for 60 seconds, and other cameras keep detecting. 4. The camera resumes Active detection after the cooldown with no duplicate alert for the same stimulus. | F6: 46262 | G6: Pass | H6: All four acceptance conditions observed on a live detection. The alert left the active queue immediately on Dismiss and the blocking modal closed. The incident record reads Dismissed and names the acting user: verified_by_id 2 (dsahagun) with verified_at 09:54:14.771488. Note on the schema, checked against app/services/incidents.py: any transition out of Unverified records the actor in verified_by_id rather than closed_by_id, so closed_by_id is null on this false-positive path by design. The actor is additionally in the audit trail as audit_id 65 ALERT_DISMISS, dsahagun, Operator, success. Only the affected camera paused, with desired_state_reason cooldown and a cooldown_until exactly 60.0 seconds after the dismissal instant, while cameras 2 and 5 remained ai_status Active throughout. After expiry camera 1 returned to desired_ai_state Active with reason None and cooldown_until cleared, and no duplicate incident was created for the same stimulus during or immediately after the cooldown. | I6: https://docs.google.com/spreadsheets/d/127sqg1pWCKvnr1KYa2ctscpMyJDphAcq6-xflAvkjJ0/edit?gid=0#gid=0&range=A6:J6 | J6: No additional defect note was recorded in the tracker.
A7: TC-SYS-006 | B7: FR-07 Audible Alert Timeout and Escalation / FR-09 Human-in-the-Loop (HITL) Verification Workflow | C7: The snooze window expires and re-alarms before the operator reaches a decision. | D7: 1. Set the operator's snooze duration to its minimum of 15 seconds. 2. On a live alert (log_id 19), select Snooze alarm and read snoozed_at and snoozed_until. 3. Instrument HTMLMediaElement.play() in the page, take no further action, and wait for the window to elapse. 4. Snooze a second time and confirm a fresh countdown. 5. Select Confirm Accident and observe whether further re-alarms occur. | E7: 1. Snooze mutes the alarm for that alert only and starts the countdown. 2. The alarm re-triggers for that alert when the window expires and the incident is still Unverified. 3. A second snooze starts a fresh countdown. 4. Confirming inside the window suppresses further re-alarms and records the snoozing user and time on the incident. | F7: 46262 | G7: Pass | H7: All four acceptance conditions observed. Snooze muted the alarm for that alert alone and started the countdown: snoozed_at 09:47:07.563581 with snoozed_until 09:47:22.563581, a window of exactly 15.0 seconds, recorded against snoozed_by_id 2, with the incident remaining Unverified. The alarm re-triggered on expiry with the incident still Unverified: an instrumented play() call fired at 09:47:22.579Z, within 16 ms of the recorded expiry. A second snooze started a fresh countdown, snoozed_at moving to 09:48:42.053260 with snoozed_until 09:48:57.053260, again exactly 15.0 seconds, and the alarm re-triggered again at 09:48:57.066Z, within 13 ms. Confirming suppressed further re-alarms: no play() call was recorded in the 30 seconds after the confirm at 09:51:23, and the snoozing user and times are preserved in the audit trail as audit_id 61 and 62 ALERT_SNOOZE by dsahagun, each carrying its snoozed_until. Note that the incident row's own snooze fields are cleared on transition out of Unverified, so the durable record of who snoozed and when is the audit trail. See DEF-006 for the alarm sound and volume used on these re-alarms, which does not affect this case's acceptance conditions. | I7: https://docs.google.com/spreadsheets/d/127sqg1pWCKvnr1KYa2ctscpMyJDphAcq6-xflAvkjJ0/edit?gid=0#gid=0&range=A7:J7 | J7: DEF-006
A8: TC-SYS-007 | B8: FR-08 Alarm Configuration Module / NFR-11 Alert Distinctiveness | C8: Alarm personalisation persists across sessions and governs the next alert. | D8: 1. Sign in as Operator and open Profile, Alarm Settings. 2. Select a different alarm sound (Buzzer), adjust the volume, and set the snooze duration inside the 15 to 60 second range. 3. Observe the save status indicator without pressing a separate save control. 4. Re-authenticate in a fresh session and confirm the settings are restored. 5. Let a live alert arrive and instrument HTMLMediaElement.play() to capture the sound file and volume actually used. | E8: 1. The preview plays the selected sound at the configured volume. 2. Settings persist automatically and the status indicator reports the saved state. 3. The same settings are restored after re-authentication. 4. The next alert uses the selected sound, volume, and snooze duration. | F8: 46262 | G8: Pass | H8: Retest passed. Four focused frontend test files passed all 32 tests. Live browser verification persisted the selected sound and volume across a fresh session; the next alert invoked digital_alarm.mp3 at volume 0.35 with loop=true. Cleanup restored the default settings. | I8: var/test-evidence/retest-sys007-20260916.json | J8: Prior DEF-006 behavior was not reproduced; the required persistence and live playback behavior was observed in this retest.
A9: TC-SYS-008 | B9: FR-09 Human-in-the-Loop (HITL) Verification Workflow / Objective 2 Real-time alert dashboard | C9: Two concurrent operator dashboards converge on a single incident decision. | D9: 1. Sign in as Operator tcselfserve in the browser as workstation A. 2. Sign in as a different Operator (ealonzo) from an independent session and open the same /ws/alerts channel the dashboard uses, with the session cookie attached on the handshake, as workstation B. 3. Let a live collision alert arrive while both are connected. 4. Confirm the alert on workstation A and observe workstation B without refreshing it. 5. Attempt a second, conflicting verification from workstation B. | E9: 1. Both workstations receive the alert and alarm. 2. After the decision on A, workstation B removes the alert from its active queue and shows the incident as Ongoing. 3. Exactly one incident record exists, attributed to the operator who acted. 4. Workstation B cannot record a second conflicting verification. | F9: 46262 | G9: Pass | H9: All four acceptance conditions observed with two genuinely independent operator sessions. Both workstations received the alert. Workstation B connected at 10:20:06.512Z, before the detection, and received NEW_DETECTION for log_id 23 at 10:21:09.921Z carrying status Unverified, camera 1 and confidence 0.841, while workstation A raised the same alert as its blocking modal. This was a live broadcast, not a reconnect replay. After the decision on A, workstation B saw the incident become Ongoing without any refresh: it received ALERT_STATUS_UPDATE for log_id 23 with status Ongoing at 10:21:25.585Z, 24 milliseconds after A's confirm was committed at 10:21:25.561576. Exactly one incident record exists for that detection, log_id 23, attributed to verified_by_id 9 (tcselfserve), the operator who acted, and not to B. Workstation B could not record a conflicting verification: its confirm was refused 409 CONFLICT_STATE with 'This incident was already handled by another operator.' and a body naming current_status Ongoing and handled_action ALERT_CONFIRM. Workstation B captured 249 frames in total across the window, comprising CONNECTION_READY, NEW_DETECTION, ALERT_STATUS_UPDATE and 246 CAMERA_STATUS_UPDATE frames. | I9: https://docs.google.com/spreadsheets/d/127sqg1pWCKvnr1KYa2ctscpMyJDphAcq6-xflAvkjJ0/edit?gid=0#gid=0&range=A9:J9 | J9: No additional defect note was recorded in the tracker.
A10: TC-SYS-009 | B10: FR-09 Human-in-the-Loop (HITL) Verification Workflow / NFR-10 Workflow Efficiency | C10: The alert decision path is reachable without intermediate navigation. | D10: 1. Let a live alert be presented on the deployed build. 2. Read the alert dialog's full control inventory from the accessibility tree and count the interactions needed to reach each recorded decision. 3. Exercise Snooze, then reach a Confirm decision, counting actions. 4. Record what information is visible without leaving the alert. | E10: 1. Confirm and Dismiss are each reachable from the presented alert in a single action, with no intermediate navigation. 2. Snooze adds exactly one action and does not reset or lengthen the decision path. 3. The snapshot, camera, timestamp, and confidence score are visible without leaving the alert. 4. The observed interaction counts are recorded for comparison with the NFR-09 timing result. | F10: 46262 | G10: Pass | H10: All four acceptance conditions observed. The presented alert is an alertdialog whose entire control inventory is Zoom snapshot, Snooze alarm, Dismiss Accident and Confirm Accident, so Confirm and Dismiss are each reachable in a single action from the alert with no intermediate navigation. A single click on Dismiss Accident removed the alert and advanced the queue from 'Alert 1 of 3' to 'Alert 1 of 2', and a single click on Confirm Accident moved log_id 19 to Ongoing. Snooze adds exactly one action and does not lengthen the decision path: it is one click in the same dialog, and after snoozing, Confirm and Dismiss remained directly available in that same dialog, with the subsequent Confirm still a single click. The snapshot with its bounding box, the camera name, the detection timestamp and the AI confidence score were all visible inside the alert without leaving it. Interaction counts recorded for comparison with the NFR-09 timing result: Confirm 1 action, Dismiss 1 action, Snooze then decide 2 actions. Also observed: the alert dialog is genuinely modal. Clicks on Log Out and on sidebar destinations were not actioned while an alert was pending, which is the intended human-in-the-loop blocking behaviour. | I10: https://docs.google.com/spreadsheets/d/127sqg1pWCKvnr1KYa2ctscpMyJDphAcq6-xflAvkjJ0/edit?gid=0#gid=0&range=A10:J10 | J10: No additional defect note was recorded in the tracker.
A11: TC-SYS-010 | B11: FR-11 True Positive Handling / FR-12 Incident Logging | C11: An operator corrects a mistaken confirmation through terminal dismissal. | D11: 1. Confirm a live alert so the incident becomes Ongoing (log_id 21). 2. Open the ongoing incident from the Ongoing incidents tray. 3. Select Dismiss Accident to correct the earlier decision. 4. Inspect the incident record, the camera state and the audit trail. | E11: 1. The incident moves from Ongoing to Dismissed and stops appearing as active. 2. Both the original verification and the correcting closure are recorded with their users and times. 3. AI detection resumes on the affected camera. 4. Both actions are present in the audit trail. | F11: 46262 | G11: Pass | H11: All four acceptance conditions observed. The incident moved from Ongoing to Dismissed and left the active set. Both decisions are recorded with their users and times: verified_by_id 9 with verified_at 10:16:49.449305 from the original confirmation, and closed_by_id 9 with closed_at 10:17:18.296552 from the correcting closure. AI detection resumed on the affected camera, and the proof is direct rather than inferred: cooldown_until stayed null, consistent with the documented rule that an operator correction resumes immediately rather than entering the 60 second false-positive cooldown, and a fresh detection on that same camera was created at 10:17:20.718594, two seconds after the correction, which is only possible if analysis had resumed. Both actions appear in the audit trail with distinct action names: ALERT_CONFIRM (audit_id 88) and ALERT_CORRECTION (89), both by tcselfserve with result success, so a correction is distinguishable from an ordinary dismissal in the trail. | I11: https://docs.google.com/spreadsheets/d/127sqg1pWCKvnr1KYa2ctscpMyJDphAcq6-xflAvkjJ0/edit?gid=0#gid=0&range=A11:J11 | J11: No additional defect note was recorded in the tracker.
A12: TC-SYS-011 | B12: FR-12 Incident Logging / FR-13 Historical Logs Search and Filtering / FR-18 Report Generation and Data Export / FR-20 Activity Audit Trail | C12: An operator filters completed incident history and exports one normal-sized report from the deployed browser. | D12: 1. Sign in and open Detections, Logs tab. 2. Apply a combined date, camera and handler filter (camera_id 1, user_id 2, 2026-09-01 to 2026-09-30 Asia/Manila). 3. Compare the returned records against a direct sqlite3 query. 4. Export the same filtered scope as CSV and compare its rows. 5. Inspect the export audit entry. Timing deliberately not recorded. | E12: 1. Filtered history shows only records matching every applied filter. 2. The export opens cleanly and its rows match the displayed filter scope exactly. 3. The export action is recorded in the audit trail with the applied filters. 4. Performance timing for exports is reported separately under Performance and Load Testing. | F12: 46262 | G12: Pass | H12: All four acceptance conditions observed. The combined filter returned exactly 2 records, log_id 1 and 2, both on camera 1 and both handled by user 2 inside the date range, matching the independent SQL result [2, 1] exactly. The CSV export opened cleanly and contained exactly those same two rows with their full lifecycle fields (Dismissed 97.0% and Cleared 93.0%, both Ayala Highway Cam, handler Daniel Luis Sahagun). The export was recorded as audit_id 53 REPORT_EXPORT carrying the applied filters start_date, end_date, camera_id [1], user_id [2] and row_count 2. No timing was recorded in this case, as instructed. | I12: https://docs.google.com/spreadsheets/d/127sqg1pWCKvnr1KYa2ctscpMyJDphAcq6-xflAvkjJ0/edit?gid=0#gid=0&range=A12:J12 | J12: No additional defect note was recorded in the tracker.
A13: TC-SYS-012 | B13: FR-12 Incident Logging / FR-13 Historical Logs Search and Filtering | C13: An operator reviews the full lifecycle of a historical incident. | D13: 1. Open Detections and locate a terminal incident in the log. 2. Search by accident number exactly as displayed, then open the record with its view action. 3. Inspect the snapshot, telemetry and lifecycle fields in the detail modal. 4. Read the modal's full control inventory to check for any edit control. | E13: 1. The modal shows the snapshot with its bounding box, the detection time, camera, and confidence score. 2. Snooze, verification, and closure actions are shown with the responsible personnel and exact times. 3. The record is read-only and offers no edit control for a terminal incident. | F13: 46262 | G13: Pass | H13: All three acceptance conditions observed. The detail modal for ACC-000021, badged DISMISSED, showed the real annotated snapshot with its red bounding box drawn on the 2K frame, the detection time 09/14/2026 17:55:24, the camera name Ayala Highway Cam and the AI confidence score 74.3%. The verification and closure actions were shown with the responsible personnel and exact times: Verified By Selfie Served at 18:16:49 and Closed By Selfie Served at 18:17:18. This particular incident carried no snooze, so no snooze row was applicable; snooze capture is evidenced separately under TC-SYS-006. The record is read-only for a terminal incident: the dialog's entire interactive inventory is 'Close incident details' and 'Zoom in on Accident snapshot', with no Confirm, Dismiss, Clear or edit control present, in contrast to the same modal opened on an Ongoing incident which does offer Dismiss Accident. Defect found while performing step 2, which does not affect these acceptance conditions: searching the accident number in the exact form the interface displays it returns no results. See DEF-007. | I13: https://docs.google.com/spreadsheets/d/127sqg1pWCKvnr1KYa2ctscpMyJDphAcq6-xflAvkjJ0/edit?gid=0#gid=0&range=A13:J13 | J13: DEF-007
... A22: TC-SYS-021 | B22: NFR-19 Session Security | C22: Logging out ends the session and stops live alert delivery. | D22: 1. Sign in as an Operator and open the live /ws/alerts channel used by the dashboard, confirming delivery. 2. Log out through the API (the same call the interface's Log Out control issues) and through the browser's Log Out control directly. 3. Attempt to navigate back to a protected page using browser history. 4. Replay the pre-logout session cookie and observe the previously open channel. | E22: 1. The session ends, the authentication cookie is cleared, and the browser returns to the login page. 2. The back navigation does not restore access and redirects to login. 3. No alert message reaches the closed client. 4. The logout is recorded in the audit trail. | F22: 46262 | G22: Pass | H22: All four acceptance conditions observed. The session ended, the cookie was rejected on the very next request (401), and in the browser the Log Out control returned to /login. Browser back navigation from a protected page after logout landed on /login rather than restoring the prior view; navigating directly to a protected route (/user/health) after logout also redirected to /login. No alert message reached the closed client: the server actively closed the previously open WebSocket with close code 4009, reason 'logout', rather than leaving it open and simply withholding frames, and 0 further frames arrived on it afterward. The logout is recorded in the audit trail (LOGOUT, result success, target_type session) with the session's revocation_reason set to 'logout'. | I22: https://docs.google.com/spreadsheets/d/127sqg1pWCKvnr1KYa2ctscpMyJDphAcq6-xflAvkjJ0/edit?gid=0#gid=0&range=A22:J22 | J22: No additional defect note was recorded in the tracker.

Sheet AI Model Validation
A1: Test ID | B1: Requirement / Objective | C1: Scenario | D1: Preconditions / Steps | E1: Expected Result / Acceptance | F1: Date Executed | G1: Result | H1: Actual Result / Notes | I1: Evidence Link | J1: Defect / Retest Note | K1: Performance Assessment
